2023-05-15 17:07:58,400 [django.request:241] [log:log_response] [ERROR] Internal Server Error: /login/
Traceback (most recent call last):
  File "C:\Users\admin\AppData\Local\Programs\Python\Python311\Lib\site-packages\django\core\handlers\exception.py", line 55, in inner
    response = get_response(request)
               ^^^^^^^^^^^^^^^^^^^^^
  File "C:\Users\admin\AppData\Local\Programs\Python\Python311\Lib\site-packages\django\core\handlers\base.py", line 204, in _get_response
    self.check_response(response, callback)
  File "C:\Users\admin\AppData\Local\Programs\Python\Python311\Lib\site-packages\django\core\handlers\base.py", line 332, in check_response
    raise ValueError(
ValueError: The view accredit.views.login didn't return an HttpResponse object. It returned None instead.
