2023-04-29 13:08:47,027 [django.request:241] [log:log_response] [WARNING] Not Found: /factory/static/images/logo-sm.png
2023-04-29 13:08:47,306 [django.request:241] [log:log_response] [WARNING] Not Found: /factory/static/images/users/avatar-1.jpg
2023-04-29 13:08:47,685 [django.request:241] [log:log_response] [WARNING] Not Found: /factory/static/images/favicon.ico
2023-04-29 13:08:49,986 [django.request:241] [log:log_response] [WARNING] Not Found: /factory/static/images/logo-sm.png
2023-04-29 13:08:49,989 [django.request:241] [log:log_response] [WARNING] Not Found: /factory/static/images/users/avatar-1.jpg
2023-04-29 18:34:20,015 [django.request:241] [log:log_response] [WARNING] Not Found: /factory/static/images/logo-sm.png
2023-04-29 18:34:20,031 [django.request:241] [log:log_response] [WARNING] Not Found: /factory/static/images/users/avatar-1.jpg
2023-04-29 18:34:20,462 [django.request:241] [log:log_response] [ERROR] Internal Server Error: /factory/sync/query_instance/
Traceback (most recent call last):
  File "C:\Users\admin\AppData\Local\Programs\Python\Python311\Lib\site-packages\requests\models.py", line 971, in json
    return complexjson.loads(self.text, **kwargs)
           ^^^^^^^^^^^^^^^^^^^^^^^^^^^^^^^^^^^^^^
  File "C:\Users\admin\AppData\Local\Programs\Python\Python311\Lib\site-packages\simplejson\__init__.py", line 525, in loads
    return _default_decoder.decode(s)
           ^^^^^^^^^^^^^^^^^^^^^^^^^^
  File "C:\Users\admin\AppData\Local\Programs\Python\Python311\Lib\site-packages\simplejson\decoder.py", line 372, in decode
    obj, end = self.raw_decode(s)
               ^^^^^^^^^^^^^^^^^^
  File "C:\Users\admin\AppData\Local\Programs\Python\Python311\Lib\site-packages\simplejson\decoder.py", line 402, in raw_decode
    return self.scan_once(s, idx=_w(s, idx).end())
           ^^^^^^^^^^^^^^^^^^^^^^^^^^^^^^^^^^^^^^^
simplejson.errors.JSONDecodeError: Expecting value: line 1 column 1 (char 0)

During handling of the above exception, another exception occurred:

Traceback (most recent call last):
  File "C:\Users\admin\AppData\Local\Programs\Python\Python311\Lib\site-packages\django\core\handlers\exception.py", line 55, in inner
    response = get_response(request)
               ^^^^^^^^^^^^^^^^^^^^^
  File "C:\Users\admin\AppData\Local\Programs\Python\Python311\Lib\site-packages\django\core\handlers\base.py", line 197, in _get_response
    response = wrapped_callback(request, *callback_args, **callback_kwargs)
               ^^^^^^^^^^^^^^^^^^^^^^^^^^^^^^^^^^^^^^^^^^^^^^^^^^^^^^^^^^^^
  File "D:\项目\data_factory_platform\data_sync\views.py", line 48, in get_instance
    data_ = online.query_instance()
            ^^^^^^^^^^^^^^^^^^^^^^^
  File "D:\项目\data_factory_platform\data_sync\business\online_data_sync.py", line 20, in query_instance
    mysql_l = jsonpath(res.json(), '$..data[?(@.db_type=="mysql")].instance_name')
                       ^^^^^^^^^^
  File "C:\Users\admin\AppData\Local\Programs\Python\Python311\Lib\site-packages\requests\models.py", line 975, in json
    raise RequestsJSONDecodeError(e.msg, e.doc, e.pos)
requests.exceptions.JSONDecodeError: Expecting value: line 1 column 1 (char 0)
2023-04-29 18:36:16,005 [django.request:241] [log:log_response] [WARNING] Not Found: /factory/static/images/logo-sm.png
2023-04-29 18:36:16,006 [django.request:241] [log:log_response] [WARNING] Not Found: /factory/static/images/users/avatar-1.jpg
2023-04-29 18:36:16,367 [django.request:241] [log:log_response] [ERROR] Internal Server Error: /factory/sync/query_instance/
Traceback (most recent call last):
  File "C:\Users\admin\AppData\Local\Programs\Python\Python311\Lib\site-packages\requests\models.py", line 971, in json
    return complexjson.loads(self.text, **kwargs)
           ^^^^^^^^^^^^^^^^^^^^^^^^^^^^^^^^^^^^^^
  File "C:\Users\admin\AppData\Local\Programs\Python\Python311\Lib\site-packages\simplejson\__init__.py", line 525, in loads
    return _default_decoder.decode(s)
           ^^^^^^^^^^^^^^^^^^^^^^^^^^
  File "C:\Users\admin\AppData\Local\Programs\Python\Python311\Lib\site-packages\simplejson\decoder.py", line 372, in decode
    obj, end = self.raw_decode(s)
               ^^^^^^^^^^^^^^^^^^
  File "C:\Users\admin\AppData\Local\Programs\Python\Python311\Lib\site-packages\simplejson\decoder.py", line 402, in raw_decode
    return self.scan_once(s, idx=_w(s, idx).end())
           ^^^^^^^^^^^^^^^^^^^^^^^^^^^^^^^^^^^^^^^
simplejson.errors.JSONDecodeError: Expecting value: line 1 column 1 (char 0)

During handling of the above exception, another exception occurred:

Traceback (most recent call last):
  File "C:\Users\admin\AppData\Local\Programs\Python\Python311\Lib\site-packages\django\core\handlers\exception.py", line 55, in inner
    response = get_response(request)
               ^^^^^^^^^^^^^^^^^^^^^
  File "C:\Users\admin\AppData\Local\Programs\Python\Python311\Lib\site-packages\django\core\handlers\base.py", line 197, in _get_response
    response = wrapped_callback(request, *callback_args, **callback_kwargs)
               ^^^^^^^^^^^^^^^^^^^^^^^^^^^^^^^^^^^^^^^^^^^^^^^^^^^^^^^^^^^^
  File "D:\项目\data_factory_platform\data_sync\views.py", line 48, in get_instance
    data_ = online.query_instance()
            ^^^^^^^^^^^^^^^^^^^^^^^
  File "D:\项目\data_factory_platform\data_sync\business\online_data_sync.py", line 20, in query_instance
    mysql_l = jsonpath(res.json(), '$..data[?(@.db_type=="mysql")].instance_name')
                       ^^^^^^^^^^
  File "C:\Users\admin\AppData\Local\Programs\Python\Python311\Lib\site-packages\requests\models.py", line 975, in json
    raise RequestsJSONDecodeError(e.msg, e.doc, e.pos)
requests.exceptions.JSONDecodeError: Expecting value: line 1 column 1 (char 0)
2023-04-29 18:38:47,077 [django.request:241] [log:log_response] [WARNING] Not Found: /factory/static/images/logo-sm.png
2023-04-29 18:38:47,078 [django.request:241] [log:log_response] [WARNING] Not Found: /factory/static/images/users/avatar-1.jpg
2023-04-29 18:38:47,807 [django.request:241] [log:log_response] [ERROR] Internal Server Error: /factory/sync/query_instance/
Traceback (most recent call last):
  File "C:\Users\admin\AppData\Local\Programs\Python\Python311\Lib\site-packages\requests\models.py", line 971, in json
    return complexjson.loads(self.text, **kwargs)
           ^^^^^^^^^^^^^^^^^^^^^^^^^^^^^^^^^^^^^^
  File "C:\Users\admin\AppData\Local\Programs\Python\Python311\Lib\site-packages\simplejson\__init__.py", line 525, in loads
    return _default_decoder.decode(s)
           ^^^^^^^^^^^^^^^^^^^^^^^^^^
  File "C:\Users\admin\AppData\Local\Programs\Python\Python311\Lib\site-packages\simplejson\decoder.py", line 372, in decode
    obj, end = self.raw_decode(s)
               ^^^^^^^^^^^^^^^^^^
  File "C:\Users\admin\AppData\Local\Programs\Python\Python311\Lib\site-packages\simplejson\decoder.py", line 402, in raw_decode
    return self.scan_once(s, idx=_w(s, idx).end())
           ^^^^^^^^^^^^^^^^^^^^^^^^^^^^^^^^^^^^^^^
simplejson.errors.JSONDecodeError: Expecting value: line 1 column 1 (char 0)

During handling of the above exception, another exception occurred:

Traceback (most recent call last):
  File "C:\Users\admin\AppData\Local\Programs\Python\Python311\Lib\site-packages\django\core\handlers\exception.py", line 55, in inner
    response = get_response(request)
               ^^^^^^^^^^^^^^^^^^^^^
  File "C:\Users\admin\AppData\Local\Programs\Python\Python311\Lib\site-packages\django\core\handlers\base.py", line 197, in _get_response
    response = wrapped_callback(request, *callback_args, **callback_kwargs)
               ^^^^^^^^^^^^^^^^^^^^^^^^^^^^^^^^^^^^^^^^^^^^^^^^^^^^^^^^^^^^
  File "D:\项目\data_factory_platform\data_sync\views.py", line 48, in get_instance
    data_ = online.query_instance()
            ^^^^^^^^^^^^^^^^^^^^^^^
  File "D:\项目\data_factory_platform\data_sync\business\online_data_sync.py", line 20, in query_instance
    mysql_l = jsonpath(res.json(), '$..data[?(@.db_type=="mysql")].instance_name')
                       ^^^^^^^^^^
  File "C:\Users\admin\AppData\Local\Programs\Python\Python311\Lib\site-packages\requests\models.py", line 975, in json
    raise RequestsJSONDecodeError(e.msg, e.doc, e.pos)
requests.exceptions.JSONDecodeError: Expecting value: line 1 column 1 (char 0)
2023-04-29 18:38:49,616 [django.request:241] [log:log_response] [ERROR] Internal Server Error: /factory/query/
Traceback (most recent call last):
  File "C:\Users\admin\AppData\Local\Programs\Python\Python311\Lib\site-packages\requests\models.py", line 971, in json
    return complexjson.loads(self.text, **kwargs)
           ^^^^^^^^^^^^^^^^^^^^^^^^^^^^^^^^^^^^^^
  File "C:\Users\admin\AppData\Local\Programs\Python\Python311\Lib\site-packages\simplejson\__init__.py", line 525, in loads
    return _default_decoder.decode(s)
           ^^^^^^^^^^^^^^^^^^^^^^^^^^
  File "C:\Users\admin\AppData\Local\Programs\Python\Python311\Lib\site-packages\simplejson\decoder.py", line 372, in decode
    obj, end = self.raw_decode(s)
               ^^^^^^^^^^^^^^^^^^
  File "C:\Users\admin\AppData\Local\Programs\Python\Python311\Lib\site-packages\simplejson\decoder.py", line 402, in raw_decode
    return self.scan_once(s, idx=_w(s, idx).end())
           ^^^^^^^^^^^^^^^^^^^^^^^^^^^^^^^^^^^^^^^
simplejson.errors.JSONDecodeError: Expecting value: line 1 column 1 (char 0)

During handling of the above exception, another exception occurred:

Traceback (most recent call last):
  File "C:\Users\admin\AppData\Local\Programs\Python\Python311\Lib\site-packages\django\core\handlers\exception.py", line 55, in inner
    response = get_response(request)
               ^^^^^^^^^^^^^^^^^^^^^
  File "C:\Users\admin\AppData\Local\Programs\Python\Python311\Lib\site-packages\django\core\handlers\base.py", line 197, in _get_response
    response = wrapped_callback(request, *callback_args, **callback_kwargs)
               ^^^^^^^^^^^^^^^^^^^^^^^^^^^^^^^^^^^^^^^^^^^^^^^^^^^^^^^^^^^^
  File "C:\Users\admin\AppData\Local\Programs\Python\Python311\Lib\site-packages\django\views\decorators\csrf.py", line 54, in wrapped_view
    return view_func(*args, **kwargs)
           ^^^^^^^^^^^^^^^^^^^^^^^^^^
  File "D:\项目\data_factory_platform\data_sync\views.py", line 89, in query
    data = on.query({
           ^^^^^^^^^^
  File "D:\项目\data_factory_platform\data_sync\business\online_data_sync.py", line 55, in query
    return res.json()
           ^^^^^^^^^^
  File "C:\Users\admin\AppData\Local\Programs\Python\Python311\Lib\site-packages\requests\models.py", line 975, in json
    raise RequestsJSONDecodeError(e.msg, e.doc, e.pos)
requests.exceptions.JSONDecodeError: Expecting value: line 1 column 1 (char 0)
2023-04-29 18:39:59,108 [django.request:241] [log:log_response] [WARNING] Not Found: /factory/static/images/users/avatar-1.jpg
2023-04-29 18:39:59,109 [django.request:241] [log:log_response] [WARNING] Not Found: /factory/static/images/logo-sm.png
2023-04-29 18:39:59,608 [django.request:241] [log:log_response] [ERROR] Internal Server Error: /factory/sync/query_instance/
Traceback (most recent call last):
  File "C:\Users\admin\AppData\Local\Programs\Python\Python311\Lib\site-packages\requests\models.py", line 971, in json
    return complexjson.loads(self.text, **kwargs)
           ^^^^^^^^^^^^^^^^^^^^^^^^^^^^^^^^^^^^^^
  File "C:\Users\admin\AppData\Local\Programs\Python\Python311\Lib\site-packages\simplejson\__init__.py", line 525, in loads
    return _default_decoder.decode(s)
           ^^^^^^^^^^^^^^^^^^^^^^^^^^
  File "C:\Users\admin\AppData\Local\Programs\Python\Python311\Lib\site-packages\simplejson\decoder.py", line 372, in decode
    obj, end = self.raw_decode(s)
               ^^^^^^^^^^^^^^^^^^
  File "C:\Users\admin\AppData\Local\Programs\Python\Python311\Lib\site-packages\simplejson\decoder.py", line 402, in raw_decode
    return self.scan_once(s, idx=_w(s, idx).end())
           ^^^^^^^^^^^^^^^^^^^^^^^^^^^^^^^^^^^^^^^
simplejson.errors.JSONDecodeError: Expecting value: line 1 column 1 (char 0)

During handling of the above exception, another exception occurred:

Traceback (most recent call last):
  File "C:\Users\admin\AppData\Local\Programs\Python\Python311\Lib\site-packages\django\core\handlers\exception.py", line 55, in inner
    response = get_response(request)
               ^^^^^^^^^^^^^^^^^^^^^
  File "C:\Users\admin\AppData\Local\Programs\Python\Python311\Lib\site-packages\django\core\handlers\base.py", line 197, in _get_response
    response = wrapped_callback(request, *callback_args, **callback_kwargs)
               ^^^^^^^^^^^^^^^^^^^^^^^^^^^^^^^^^^^^^^^^^^^^^^^^^^^^^^^^^^^^
  File "D:\项目\data_factory_platform\data_sync\views.py", line 48, in get_instance
    data_ = online.query_instance()
            ^^^^^^^^^^^^^^^^^^^^^^^
  File "D:\项目\data_factory_platform\data_sync\business\online_data_sync.py", line 20, in query_instance
    mysql_l = jsonpath(res.json(), '$..data[?(@.db_type=="mysql")].instance_name')
                       ^^^^^^^^^^
  File "C:\Users\admin\AppData\Local\Programs\Python\Python311\Lib\site-packages\requests\models.py", line 975, in json
    raise RequestsJSONDecodeError(e.msg, e.doc, e.pos)
requests.exceptions.JSONDecodeError: Expecting value: line 1 column 1 (char 0)
2023-04-29 18:40:01,674 [django.request:241] [log:log_response] [ERROR] Internal Server Error: /factory/query/
Traceback (most recent call last):
  File "C:\Users\admin\AppData\Local\Programs\Python\Python311\Lib\site-packages\requests\models.py", line 971, in json
    return complexjson.loads(self.text, **kwargs)
           ^^^^^^^^^^^^^^^^^^^^^^^^^^^^^^^^^^^^^^
  File "C:\Users\admin\AppData\Local\Programs\Python\Python311\Lib\site-packages\simplejson\__init__.py", line 525, in loads
    return _default_decoder.decode(s)
           ^^^^^^^^^^^^^^^^^^^^^^^^^^
  File "C:\Users\admin\AppData\Local\Programs\Python\Python311\Lib\site-packages\simplejson\decoder.py", line 372, in decode
    obj, end = self.raw_decode(s)
               ^^^^^^^^^^^^^^^^^^
  File "C:\Users\admin\AppData\Local\Programs\Python\Python311\Lib\site-packages\simplejson\decoder.py", line 402, in raw_decode
    return self.scan_once(s, idx=_w(s, idx).end())
           ^^^^^^^^^^^^^^^^^^^^^^^^^^^^^^^^^^^^^^^
simplejson.errors.JSONDecodeError: Expecting value: line 1 column 1 (char 0)

During handling of the above exception, another exception occurred:

Traceback (most recent call last):
  File "C:\Users\admin\AppData\Local\Programs\Python\Python311\Lib\site-packages\django\core\handlers\exception.py", line 55, in inner
    response = get_response(request)
               ^^^^^^^^^^^^^^^^^^^^^
  File "C:\Users\admin\AppData\Local\Programs\Python\Python311\Lib\site-packages\django\core\handlers\base.py", line 197, in _get_response
    response = wrapped_callback(request, *callback_args, **callback_kwargs)
               ^^^^^^^^^^^^^^^^^^^^^^^^^^^^^^^^^^^^^^^^^^^^^^^^^^^^^^^^^^^^
  File "C:\Users\admin\AppData\Local\Programs\Python\Python311\Lib\site-packages\django\views\decorators\csrf.py", line 54, in wrapped_view
    return view_func(*args, **kwargs)
           ^^^^^^^^^^^^^^^^^^^^^^^^^^
  File "D:\项目\data_factory_platform\data_sync\views.py", line 89, in query
    data = on.query({
           ^^^^^^^^^^
  File "D:\项目\data_factory_platform\data_sync\business\online_data_sync.py", line 55, in query
    return res.json()
           ^^^^^^^^^^
  File "C:\Users\admin\AppData\Local\Programs\Python\Python311\Lib\site-packages\requests\models.py", line 975, in json
    raise RequestsJSONDecodeError(e.msg, e.doc, e.pos)
requests.exceptions.JSONDecodeError: Expecting value: line 1 column 1 (char 0)
2023-04-29 18:40:14,701 [django.request:241] [log:log_response] [ERROR] Internal Server Error: /factory/sync/query_instance/
Traceback (most recent call last):
  File "C:\Users\admin\AppData\Local\Programs\Python\Python311\Lib\site-packages\requests\models.py", line 971, in json
    return complexjson.loads(self.text, **kwargs)
           ^^^^^^^^^^^^^^^^^^^^^^^^^^^^^^^^^^^^^^
  File "C:\Users\admin\AppData\Local\Programs\Python\Python311\Lib\site-packages\simplejson\__init__.py", line 525, in loads
    return _default_decoder.decode(s)
           ^^^^^^^^^^^^^^^^^^^^^^^^^^
  File "C:\Users\admin\AppData\Local\Programs\Python\Python311\Lib\site-packages\simplejson\decoder.py", line 372, in decode
    obj, end = self.raw_decode(s)
               ^^^^^^^^^^^^^^^^^^
  File "C:\Users\admin\AppData\Local\Programs\Python\Python311\Lib\site-packages\simplejson\decoder.py", line 402, in raw_decode
    return self.scan_once(s, idx=_w(s, idx).end())
           ^^^^^^^^^^^^^^^^^^^^^^^^^^^^^^^^^^^^^^^
simplejson.errors.JSONDecodeError: Expecting value: line 1 column 1 (char 0)

During handling of the above exception, another exception occurred:

Traceback (most recent call last):
  File "C:\Users\admin\AppData\Local\Programs\Python\Python311\Lib\site-packages\django\core\handlers\exception.py", line 55, in inner
    response = get_response(request)
               ^^^^^^^^^^^^^^^^^^^^^
  File "C:\Users\admin\AppData\Local\Programs\Python\Python311\Lib\site-packages\django\core\handlers\base.py", line 197, in _get_response
    response = wrapped_callback(request, *callback_args, **callback_kwargs)
               ^^^^^^^^^^^^^^^^^^^^^^^^^^^^^^^^^^^^^^^^^^^^^^^^^^^^^^^^^^^^
  File "D:\项目\data_factory_platform\data_sync\views.py", line 48, in get_instance
    data_ = online.query_instance()
            ^^^^^^^^^^^^^^^^^^^^^^^
  File "D:\项目\data_factory_platform\data_sync\business\online_data_sync.py", line 20, in query_instance
    mysql_l = jsonpath(res.json(), '$..data[?(@.db_type=="mysql")].instance_name')
                       ^^^^^^^^^^
  File "C:\Users\admin\AppData\Local\Programs\Python\Python311\Lib\site-packages\requests\models.py", line 975, in json
    raise RequestsJSONDecodeError(e.msg, e.doc, e.pos)
requests.exceptions.JSONDecodeError: Expecting value: line 1 column 1 (char 0)
2023-04-29 18:40:14,857 [django.request:241] [log:log_response] [WARNING] Not Found: /favicon.ico
2023-04-29 18:41:26,712 [django.request:241] [log:log_response] [WARNING] Not Found: /factory/static/images/users/avatar-1.jpg
2023-04-29 18:41:26,713 [django.request:241] [log:log_response] [WARNING] Not Found: /factory/static/images/logo-sm.png
2023-04-29 18:41:27,552 [django.request:241] [log:log_response] [ERROR] Internal Server Error: /factory/sync/query_instance/
Traceback (most recent call last):
  File "C:\Users\admin\AppData\Local\Programs\Python\Python311\Lib\site-packages\requests\models.py", line 971, in json
    return complexjson.loads(self.text, **kwargs)
           ^^^^^^^^^^^^^^^^^^^^^^^^^^^^^^^^^^^^^^
  File "C:\Users\admin\AppData\Local\Programs\Python\Python311\Lib\site-packages\simplejson\__init__.py", line 525, in loads
    return _default_decoder.decode(s)
           ^^^^^^^^^^^^^^^^^^^^^^^^^^
  File "C:\Users\admin\AppData\Local\Programs\Python\Python311\Lib\site-packages\simplejson\decoder.py", line 372, in decode
    obj, end = self.raw_decode(s)
               ^^^^^^^^^^^^^^^^^^
  File "C:\Users\admin\AppData\Local\Programs\Python\Python311\Lib\site-packages\simplejson\decoder.py", line 402, in raw_decode
    return self.scan_once(s, idx=_w(s, idx).end())
           ^^^^^^^^^^^^^^^^^^^^^^^^^^^^^^^^^^^^^^^
simplejson.errors.JSONDecodeError: Expecting value: line 1 column 1 (char 0)

During handling of the above exception, another exception occurred:

Traceback (most recent call last):
  File "C:\Users\admin\AppData\Local\Programs\Python\Python311\Lib\site-packages\django\core\handlers\exception.py", line 55, in inner
    response = get_response(request)
               ^^^^^^^^^^^^^^^^^^^^^
  File "C:\Users\admin\AppData\Local\Programs\Python\Python311\Lib\site-packages\django\core\handlers\base.py", line 197, in _get_response
    response = wrapped_callback(request, *callback_args, **callback_kwargs)
               ^^^^^^^^^^^^^^^^^^^^^^^^^^^^^^^^^^^^^^^^^^^^^^^^^^^^^^^^^^^^
  File "D:\项目\data_factory_platform\data_sync\views.py", line 48, in get_instance
    data_ = online.query_instance()
            ^^^^^^^^^^^^^^^^^^^^^^^
  File "D:\项目\data_factory_platform\data_sync\business\online_data_sync.py", line 20, in query_instance
    mysql_l = jsonpath(res.json(), '$..data[?(@.db_type=="mysql")].instance_name')
                       ^^^^^^^^^^
  File "C:\Users\admin\AppData\Local\Programs\Python\Python311\Lib\site-packages\requests\models.py", line 975, in json
    raise RequestsJSONDecodeError(e.msg, e.doc, e.pos)
requests.exceptions.JSONDecodeError: Expecting value: line 1 column 1 (char 0)
2023-04-29 18:41:27,609 [django.request:241] [log:log_response] [WARNING] Not Found: /factory/static/images/favicon.ico
2023-04-29 18:41:34,768 [django.request:241] [log:log_response] [ERROR] Internal Server Error: /factory/query/
Traceback (most recent call last):
  File "C:\Users\admin\AppData\Local\Programs\Python\Python311\Lib\site-packages\requests\models.py", line 971, in json
    return complexjson.loads(self.text, **kwargs)
           ^^^^^^^^^^^^^^^^^^^^^^^^^^^^^^^^^^^^^^
  File "C:\Users\admin\AppData\Local\Programs\Python\Python311\Lib\site-packages\simplejson\__init__.py", line 525, in loads
    return _default_decoder.decode(s)
           ^^^^^^^^^^^^^^^^^^^^^^^^^^
  File "C:\Users\admin\AppData\Local\Programs\Python\Python311\Lib\site-packages\simplejson\decoder.py", line 372, in decode
    obj, end = self.raw_decode(s)
               ^^^^^^^^^^^^^^^^^^
  File "C:\Users\admin\AppData\Local\Programs\Python\Python311\Lib\site-packages\simplejson\decoder.py", line 402, in raw_decode
    return self.scan_once(s, idx=_w(s, idx).end())
           ^^^^^^^^^^^^^^^^^^^^^^^^^^^^^^^^^^^^^^^
simplejson.errors.JSONDecodeError: Expecting value: line 1 column 1 (char 0)

During handling of the above exception, another exception occurred:

Traceback (most recent call last):
  File "C:\Users\admin\AppData\Local\Programs\Python\Python311\Lib\site-packages\django\core\handlers\exception.py", line 55, in inner
    response = get_response(request)
               ^^^^^^^^^^^^^^^^^^^^^
  File "C:\Users\admin\AppData\Local\Programs\Python\Python311\Lib\site-packages\django\core\handlers\base.py", line 197, in _get_response
    response = wrapped_callback(request, *callback_args, **callback_kwargs)
               ^^^^^^^^^^^^^^^^^^^^^^^^^^^^^^^^^^^^^^^^^^^^^^^^^^^^^^^^^^^^
  File "C:\Users\admin\AppData\Local\Programs\Python\Python311\Lib\site-packages\django\views\decorators\csrf.py", line 54, in wrapped_view
    return view_func(*args, **kwargs)
           ^^^^^^^^^^^^^^^^^^^^^^^^^^
  File "D:\项目\data_factory_platform\data_sync\views.py", line 89, in query
    data = on.query({
           ^^^^^^^^^^
  File "D:\项目\data_factory_platform\data_sync\business\online_data_sync.py", line 55, in query
    return res.json()
           ^^^^^^^^^^
  File "C:\Users\admin\AppData\Local\Programs\Python\Python311\Lib\site-packages\requests\models.py", line 975, in json
    raise RequestsJSONDecodeError(e.msg, e.doc, e.pos)
requests.exceptions.JSONDecodeError: Expecting value: line 1 column 1 (char 0)
2023-04-29 18:47:21,908 [django.request:241] [log:log_response] [ERROR] Internal Server Error: /factory/query/
Traceback (most recent call last):
  File "C:\Users\admin\AppData\Local\Programs\Python\Python311\Lib\site-packages\requests\models.py", line 971, in json
    return complexjson.loads(self.text, **kwargs)
           ^^^^^^^^^^^^^^^^^^^^^^^^^^^^^^^^^^^^^^
  File "C:\Users\admin\AppData\Local\Programs\Python\Python311\Lib\site-packages\simplejson\__init__.py", line 525, in loads
    return _default_decoder.decode(s)
           ^^^^^^^^^^^^^^^^^^^^^^^^^^
  File "C:\Users\admin\AppData\Local\Programs\Python\Python311\Lib\site-packages\simplejson\decoder.py", line 372, in decode
    obj, end = self.raw_decode(s)
               ^^^^^^^^^^^^^^^^^^
  File "C:\Users\admin\AppData\Local\Programs\Python\Python311\Lib\site-packages\simplejson\decoder.py", line 402, in raw_decode
    return self.scan_once(s, idx=_w(s, idx).end())
           ^^^^^^^^^^^^^^^^^^^^^^^^^^^^^^^^^^^^^^^
simplejson.errors.JSONDecodeError: Expecting value: line 1 column 1 (char 0)

During handling of the above exception, another exception occurred:

Traceback (most recent call last):
  File "C:\Users\admin\AppData\Local\Programs\Python\Python311\Lib\site-packages\django\core\handlers\exception.py", line 55, in inner
    response = get_response(request)
               ^^^^^^^^^^^^^^^^^^^^^
  File "C:\Users\admin\AppData\Local\Programs\Python\Python311\Lib\site-packages\django\core\handlers\base.py", line 197, in _get_response
    response = wrapped_callback(request, *callback_args, **callback_kwargs)
               ^^^^^^^^^^^^^^^^^^^^^^^^^^^^^^^^^^^^^^^^^^^^^^^^^^^^^^^^^^^^
  File "C:\Users\admin\AppData\Local\Programs\Python\Python311\Lib\site-packages\django\views\decorators\csrf.py", line 54, in wrapped_view
    return view_func(*args, **kwargs)
           ^^^^^^^^^^^^^^^^^^^^^^^^^^
  File "D:\项目\data_factory_platform\data_sync\views.py", line 89, in query
    data = on.query({
           ^^^^^^^^^^
  File "D:\项目\data_factory_platform\data_sync\business\online_data_sync.py", line 55, in query
    return res.json()
           ^^^^^^^^^^
  File "C:\Users\admin\AppData\Local\Programs\Python\Python311\Lib\site-packages\requests\models.py", line 975, in json
    raise RequestsJSONDecodeError(e.msg, e.doc, e.pos)
requests.exceptions.JSONDecodeError: Expecting value: line 1 column 1 (char 0)
2023-04-29 18:48:16,150 [django.request:241] [log:log_response] [ERROR] Internal Server Error: /factory/query/
Traceback (most recent call last):
  File "C:\Users\admin\AppData\Local\Programs\Python\Python311\Lib\site-packages\requests\models.py", line 971, in json
    return complexjson.loads(self.text, **kwargs)
           ^^^^^^^^^^^^^^^^^^^^^^^^^^^^^^^^^^^^^^
  File "C:\Users\admin\AppData\Local\Programs\Python\Python311\Lib\site-packages\simplejson\__init__.py", line 525, in loads
    return _default_decoder.decode(s)
           ^^^^^^^^^^^^^^^^^^^^^^^^^^
  File "C:\Users\admin\AppData\Local\Programs\Python\Python311\Lib\site-packages\simplejson\decoder.py", line 372, in decode
    obj, end = self.raw_decode(s)
               ^^^^^^^^^^^^^^^^^^
  File "C:\Users\admin\AppData\Local\Programs\Python\Python311\Lib\site-packages\simplejson\decoder.py", line 402, in raw_decode
    return self.scan_once(s, idx=_w(s, idx).end())
           ^^^^^^^^^^^^^^^^^^^^^^^^^^^^^^^^^^^^^^^
simplejson.errors.JSONDecodeError: Expecting value: line 1 column 1 (char 0)

During handling of the above exception, another exception occurred:

Traceback (most recent call last):
  File "C:\Users\admin\AppData\Local\Programs\Python\Python311\Lib\site-packages\django\core\handlers\exception.py", line 55, in inner
    response = get_response(request)
               ^^^^^^^^^^^^^^^^^^^^^
  File "C:\Users\admin\AppData\Local\Programs\Python\Python311\Lib\site-packages\django\core\handlers\base.py", line 197, in _get_response
    response = wrapped_callback(request, *callback_args, **callback_kwargs)
               ^^^^^^^^^^^^^^^^^^^^^^^^^^^^^^^^^^^^^^^^^^^^^^^^^^^^^^^^^^^^
  File "C:\Users\admin\AppData\Local\Programs\Python\Python311\Lib\site-packages\django\views\decorators\csrf.py", line 54, in wrapped_view
    return view_func(*args, **kwargs)
           ^^^^^^^^^^^^^^^^^^^^^^^^^^
  File "D:\项目\data_factory_platform\data_sync\views.py", line 89, in query
    data = on.query({
           ^^^^^^^^^^
  File "D:\项目\data_factory_platform\data_sync\business\online_data_sync.py", line 56, in query
    return res.json()
           ^^^^^^^^^^
  File "C:\Users\admin\AppData\Local\Programs\Python\Python311\Lib\site-packages\requests\models.py", line 975, in json
    raise RequestsJSONDecodeError(e.msg, e.doc, e.pos)
requests.exceptions.JSONDecodeError: Expecting value: line 1 column 1 (char 0)
2023-04-29 19:39:23,472 [django.request:241] [log:log_response] [WARNING] Not Found: /factory/static/images/logo-sm.png
2023-04-29 19:39:23,473 [django.request:241] [log:log_response] [WARNING] Not Found: /factory/static/images/users/avatar-1.jpg
2023-04-29 19:39:23,938 [django.request:241] [log:log_response] [WARNING] Not Found: /factory/static/images/users/avatar-1.jpg
2023-04-29 19:39:23,939 [django.request:241] [log:log_response] [WARNING] Not Found: /factory/static/images/logo-sm.png
2023-04-29 19:40:45,241 [django.request:241] [log:log_response] [WARNING] Not Found: /factory/static/images/logo-sm.png
2023-04-29 19:40:45,244 [django.request:241] [log:log_response] [WARNING] Not Found: /factory/static/images/users/avatar-1.jpg
2023-04-29 19:40:47,391 [django.request:241] [log:log_response] [WARNING] Not Found: /factory/static/images/favicon.ico
2023-04-29 19:55:28,057 [django.request:241] [log:log_response] [WARNING] Not Found: /factory/static/images/logo-sm.png
2023-04-29 19:55:28,058 [django.request:241] [log:log_response] [WARNING] Not Found: /factory/static/images/users/avatar-1.jpg
2023-04-29 20:15:23,472 [django.request:241] [log:log_response] [WARNING] Not Found: /factory/static/images/users/avatar-1.jpg
2023-04-29 20:15:23,474 [django.request:241] [log:log_response] [WARNING] Not Found: /factory/static/images/logo-sm.png
2023-04-29 20:16:10,504 [django.request:241] [log:log_response] [WARNING] Not Found: /factory/static/images/logo-sm.png
2023-04-29 20:16:10,505 [django.request:241] [log:log_response] [WARNING] Not Found: /factory/static/images/users/avatar-1.jpg
2023-04-29 20:20:02,360 [django.request:241] [log:log_response] [WARNING] Not Found: /factory/static/images/logo-sm.png
2023-04-29 20:20:02,361 [django.request:241] [log:log_response] [WARNING] Not Found: /factory/static/images/users/avatar-1.jpg
2023-04-29 20:22:35,749 [django.request:241] [log:log_response] [WARNING] Not Found: /factory/static/images/users/avatar-1.jpg
2023-04-29 20:22:35,750 [django.request:241] [log:log_response] [WARNING] Not Found: /factory/static/images/logo-sm.png
2023-04-29 20:26:53,297 [django.request:241] [log:log_response] [WARNING] Not Found: /factory/static/images/users/avatar-1.jpg
2023-04-29 20:26:53,298 [django.request:241] [log:log_response] [WARNING] Not Found: /factory/static/images/logo-sm.png
2023-04-29 20:28:03,921 [django.request:241] [log:log_response] [WARNING] Not Found: /factory/static/images/logo-sm.png
2023-04-29 20:28:03,923 [django.request:241] [log:log_response] [WARNING] Not Found: /factory/static/images/users/avatar-1.jpg
2023-04-29 20:28:46,851 [django.request:241] [log:log_response] [WARNING] Not Found: /factory/static/images/logo-sm.png
2023-04-29 20:28:46,853 [django.request:241] [log:log_response] [WARNING] Not Found: /factory/static/images/users/avatar-1.jpg
2023-04-29 20:29:06,186 [django.request:241] [log:log_response] [WARNING] Not Found: /factory/static/images/users/avatar-1.jpg
2023-04-29 20:29:06,188 [django.request:241] [log:log_response] [WARNING] Not Found: /factory/static/images/logo-sm.png
2023-04-29 20:29:39,696 [django.request:241] [log:log_response] [WARNING] Not Found: /factory/static/images/users/avatar-1.jpg
2023-04-29 20:29:39,697 [django.request:241] [log:log_response] [WARNING] Not Found: /factory/static/images/logo-sm.png
2023-04-29 20:30:08,756 [django.request:241] [log:log_response] [WARNING] Not Found: /factory/static/images/users/avatar-1.jpg
2023-04-29 20:30:08,758 [django.request:241] [log:log_response] [WARNING] Not Found: /factory/static/images/logo-sm.png
2023-04-29 20:31:39,118 [django.request:241] [log:log_response] [WARNING] Not Found: /factory/static/images/users/avatar-1.jpg
2023-04-29 20:31:39,120 [django.request:241] [log:log_response] [WARNING] Not Found: /factory/static/images/logo-sm.png
2023-04-29 20:36:04,216 [django.request:241] [log:log_response] [WARNING] Not Found: /factory/static/images/users/avatar-1.jpg
2023-04-29 20:36:04,218 [django.request:241] [log:log_response] [WARNING] Not Found: /factory/static/images/logo-sm.png
2023-04-29 20:38:26,430 [django.request:241] [log:log_response] [WARNING] Not Found: /factory/static/images/users/avatar-1.jpg
2023-04-29 20:38:26,431 [django.request:241] [log:log_response] [WARNING] Not Found: /factory/static/images/logo-sm.png
2023-04-29 20:44:00,570 [django.request:241] [log:log_response] [WARNING] Not Found: /factory/static/images/logo-sm.png
2023-04-29 20:44:00,572 [django.request:241] [log:log_response] [WARNING] Not Found: /factory/static/images/users/avatar-1.jpg
2023-04-29 20:46:17,954 [django.request:241] [log:log_response] [WARNING] Not Found: /factory/static/images/users/avatar-1.jpg
2023-04-29 20:46:17,954 [django.request:241] [log:log_response] [WARNING] Not Found: /factory/static/images/logo-sm.png
2023-04-29 20:47:10,756 [django.request:241] [log:log_response] [WARNING] Not Found: /factory/static/images/logo-sm.png
2023-04-29 20:47:10,759 [django.request:241] [log:log_response] [WARNING] Not Found: /factory/static/images/users/avatar-1.jpg
2023-04-29 20:50:00,250 [django.request:241] [log:log_response] [WARNING] Not Found: /factory/static/images/users/avatar-1.jpg
2023-04-29 20:50:00,254 [django.request:241] [log:log_response] [WARNING] Not Found: /factory/static/images/logo-sm.png
2023-04-29 20:56:47,107 [django.request:241] [log:log_response] [WARNING] Not Found: /factory/intranet/static/images/logo-sm.png
2023-04-29 20:56:47,110 [django.request:241] [log:log_response] [WARNING] Not Found: /factory/intranet/static/images/users/avatar-1.jpg
2023-04-29 20:56:47,228 [django.request:241] [log:log_response] [WARNING] Not Found: /factory/intranet/static/images/favicon.ico
2023-04-29 20:57:39,046 [django.request:241] [log:log_response] [WARNING] Not Found: /factory/static/images/users/avatar-1.jpg
2023-04-29 20:57:39,047 [django.request:241] [log:log_response] [WARNING] Not Found: /factory/static/images/logo-sm.png
2023-04-29 21:01:18,775 [django.request:241] [log:log_response] [WARNING] Not Found: /factory/static/images/logo-sm.png
2023-04-29 21:01:18,776 [django.request:241] [log:log_response] [WARNING] Not Found: /factory/static/images/users/avatar-1.jpg
2023-04-29 21:01:47,655 [django.request:241] [log:log_response] [WARNING] Not Found: /factory/static/images/users/avatar-1.jpg
2023-04-29 21:01:47,655 [django.request:241] [log:log_response] [WARNING] Not Found: /factory/static/images/logo-sm.png
2023-04-29 21:04:14,293 [django.request:241] [log:log_response] [WARNING] Not Found: /factory/static/images/logo-sm.png
2023-04-29 21:04:14,295 [django.request:241] [log:log_response] [WARNING] Not Found: /factory/static/images/users/avatar-1.jpg
2023-04-29 21:05:37,208 [django.request:241] [log:log_response] [WARNING] Not Found: /factory/static/images/logo-sm.png
2023-04-29 21:05:37,210 [django.request:241] [log:log_response] [WARNING] Not Found: /factory/static/images/users/avatar-1.jpg
2023-04-29 21:05:47,518 [django.request:241] [log:log_response] [WARNING] Not Found: /factory/static/images/logo-sm.png
2023-04-29 21:05:47,520 [django.request:241] [log:log_response] [WARNING] Not Found: /factory/static/images/users/avatar-1.jpg
2023-04-29 21:06:13,429 [django.request:241] [log:log_response] [WARNING] Not Found: /factory/static/images/logo-sm.png
2023-04-29 21:06:13,431 [django.request:241] [log:log_response] [WARNING] Not Found: /factory/static/images/users/avatar-1.jpg
2023-04-29 21:07:10,942 [django.request:241] [log:log_response] [WARNING] Not Found: /factory/static/images/logo-sm.png
2023-04-29 21:07:10,943 [django.request:241] [log:log_response] [WARNING] Not Found: /factory/static/images/users/avatar-1.jpg
2023-04-29 21:08:54,319 [django.request:241] [log:log_response] [WARNING] Not Found: /factory/static/images/logo-sm.png
2023-04-29 21:08:54,320 [django.request:241] [log:log_response] [WARNING] Not Found: /factory/static/images/users/avatar-1.jpg
2023-04-29 21:11:49,234 [django.request:241] [log:log_response] [WARNING] Not Found: /factory/static/images/users/avatar-1.jpg
2023-04-29 21:11:49,236 [django.request:241] [log:log_response] [WARNING] Not Found: /factory/static/images/logo-sm.png
2023-04-29 21:15:01,773 [django.request:241] [log:log_response] [WARNING] Not Found: /factory/static/images/logo-sm.png
2023-04-29 21:15:01,774 [django.request:241] [log:log_response] [WARNING] Not Found: /factory/static/images/users/avatar-1.jpg
2023-04-29 21:15:46,311 [django.request:241] [log:log_response] [WARNING] Not Found: /factory/static/images/users/avatar-1.jpg
2023-04-29 21:15:46,312 [django.request:241] [log:log_response] [WARNING] Not Found: /factory/static/images/logo-sm.png
2023-04-29 21:19:23,681 [django.request:241] [log:log_response] [WARNING] Not Found: /factory/static/images/logo-sm.png
2023-04-29 21:19:23,682 [django.request:241] [log:log_response] [WARNING] Not Found: /factory/static/images/users/avatar-1.jpg
2023-04-29 21:20:06,049 [django.request:241] [log:log_response] [WARNING] Not Found: /factory/static/images/logo-sm.png
2023-04-29 21:20:06,050 [django.request:241] [log:log_response] [WARNING] Not Found: /factory/static/images/users/avatar-1.jpg
2023-04-29 21:20:26,652 [django.request:241] [log:log_response] [WARNING] Not Found: /factory/static/images/users/avatar-1.jpg
2023-04-29 21:20:26,653 [django.request:241] [log:log_response] [WARNING] Not Found: /factory/static/images/logo-sm.png
2023-04-29 21:21:17,319 [django.request:241] [log:log_response] [WARNING] Not Found: /factory/static/images/users/avatar-1.jpg
2023-04-29 21:21:17,321 [django.request:241] [log:log_response] [WARNING] Not Found: /factory/static/images/logo-sm.png
2023-04-29 21:23:23,479 [django.request:241] [log:log_response] [WARNING] Not Found: /factory/static/images/users/avatar-1.jpg
2023-04-29 21:23:23,482 [django.request:241] [log:log_response] [WARNING] Not Found: /factory/static/images/logo-sm.png
2023-04-29 21:24:39,424 [django.request:241] [log:log_response] [WARNING] Not Found: /factory/static/images/users/avatar-1.jpg
2023-04-29 21:24:39,426 [django.request:241] [log:log_response] [WARNING] Not Found: /factory/static/images/logo-sm.png
2023-04-29 21:25:03,563 [django.request:241] [log:log_response] [WARNING] Not Found: /factory/static/images/logo-sm.png
2023-04-29 21:25:03,565 [django.request:241] [log:log_response] [WARNING] Not Found: /factory/static/images/users/avatar-1.jpg
2023-04-29 21:25:26,006 [django.request:241] [log:log_response] [WARNING] Not Found: /factory/static/images/logo-sm.png
2023-04-29 21:25:26,007 [django.request:241] [log:log_response] [WARNING] Not Found: /factory/static/images/users/avatar-1.jpg
2023-04-29 21:27:13,507 [django.request:241] [log:log_response] [WARNING] Not Found: /factory/static/images/logo-sm.png
2023-04-29 21:27:13,520 [django.request:241] [log:log_response] [WARNING] Not Found: /factory/static/images/users/avatar-1.jpg
2023-04-29 21:33:24,151 [django.request:241] [log:log_response] [WARNING] Not Found: /factory/static/images/logo-sm.png
2023-04-29 21:33:24,153 [django.request:241] [log:log_response] [WARNING] Not Found: /factory/static/images/users/avatar-1.jpg
2023-04-29 21:37:55,604 [django.request:241] [log:log_response] [WARNING] Not Found: /factory/static/images/logo-sm.png
2023-04-29 21:37:55,625 [django.request:241] [log:log_response] [WARNING] Not Found: /factory/static/images/users/avatar-1.jpg
2023-04-29 21:38:19,984 [django.request:241] [log:log_response] [WARNING] Not Found: /factory/static/images/logo-sm.png
2023-04-29 21:38:19,986 [django.request:241] [log:log_response] [WARNING] Not Found: /factory/static/images/users/avatar-1.jpg
2023-04-29 21:38:34,089 [django.request:241] [log:log_response] [WARNING] Not Found: /factory/static/images/logo-sm.png
2023-04-29 21:38:34,091 [django.request:241] [log:log_response] [WARNING] Not Found: /factory/static/images/users/avatar-1.jpg
2023-04-29 21:42:44,263 [django.request:241] [log:log_response] [WARNING] Not Found: /factory/static/images/users/avatar-1.jpg
2023-04-29 21:42:44,265 [django.request:241] [log:log_response] [WARNING] Not Found: /factory/static/images/logo-sm.png
2023-04-29 21:45:54,986 [django.request:241] [log:log_response] [WARNING] Not Found: /factory/static/images/logo-sm.png
2023-04-29 21:45:55,010 [django.request:241] [log:log_response] [WARNING] Not Found: /factory/static/images/users/avatar-1.jpg
2023-04-29 21:50:16,745 [django.request:241] [log:log_response] [WARNING] Not Found: /factory/static/images/logo-sm.png
2023-04-29 21:50:16,747 [django.request:241] [log:log_response] [WARNING] Not Found: /factory/static/images/users/avatar-1.jpg
2023-04-29 21:52:01,864 [django.request:241] [log:log_response] [WARNING] Not Found: /factory/static/images/users/avatar-1.jpg
2023-04-29 21:52:01,866 [django.request:241] [log:log_response] [WARNING] Not Found: /factory/static/images/logo-sm.png
2023-04-29 21:55:14,456 [django.request:241] [log:log_response] [WARNING] Not Found: /factory/static/images/users/avatar-1.jpg
2023-04-29 21:55:14,456 [django.request:241] [log:log_response] [WARNING] Not Found: /factory/static/images/logo-sm.png
2023-04-29 21:55:46,895 [django.request:241] [log:log_response] [WARNING] Not Found: /factory/static/images/logo-sm.png
2023-04-29 21:55:46,897 [django.request:241] [log:log_response] [WARNING] Not Found: /factory/static/images/users/avatar-1.jpg
2023-04-29 21:56:20,269 [django.request:241] [log:log_response] [WARNING] Not Found: /factory/static/images/users/avatar-1.jpg
2023-04-29 21:56:20,270 [django.request:241] [log:log_response] [WARNING] Not Found: /factory/static/images/logo-sm.png
2023-04-29 21:56:53,195 [django.request:241] [log:log_response] [WARNING] Not Found: /factory/static/images/logo-sm.png
2023-04-29 21:56:53,196 [django.request:241] [log:log_response] [WARNING] Not Found: /factory/static/images/users/avatar-1.jpg
2023-04-29 22:02:00,923 [django.request:241] [log:log_response] [WARNING] Not Found: /factory/static/images/logo-sm.png
2023-04-29 22:02:00,924 [django.request:241] [log:log_response] [WARNING] Not Found: /factory/static/images/users/avatar-1.jpg
2023-04-29 22:02:27,153 [django.request:241] [log:log_response] [WARNING] Not Found: /factory/static/images/logo-sm.png
2023-04-29 22:02:27,155 [django.request:241] [log:log_response] [WARNING] Not Found: /factory/static/images/users/avatar-1.jpg
2023-04-29 22:04:45,708 [django.request:241] [log:log_response] [WARNING] Not Found: /factory/static/images/logo-sm.png
2023-04-29 22:04:45,709 [django.request:241] [log:log_response] [WARNING] Not Found: /factory/static/images/users/avatar-1.jpg
