2023-04-29 13:08:47,027 [django.request:241] [log:log_response] [WARNING] Not Found: /factory/static/images/logo-sm.png
2023-04-29 13:08:47,306 [django.request:241] [log:log_response] [WARNING] Not Found: /factory/static/images/users/avatar-1.jpg
2023-04-29 13:08:47,685 [django.request:241] [log:log_response] [WARNING] Not Found: /factory/static/images/favicon.ico
2023-04-29 13:08:49,986 [django.request:241] [log:log_response] [WARNING] Not Found: /factory/static/images/logo-sm.png
2023-04-29 13:08:49,989 [django.request:241] [log:log_response] [WARNING] Not Found: /factory/static/images/users/avatar-1.jpg
2023-04-29 18:34:20,015 [django.request:241] [log:log_response] [WARNING] Not Found: /factory/static/images/logo-sm.png
2023-04-29 18:34:20,031 [django.request:241] [log:log_response] [WARNING] Not Found: /factory/static/images/users/avatar-1.jpg
2023-04-29 18:34:20,462 [django.request:241] [log:log_response] [ERROR] Internal Server Error: /factory/sync/query_instance/
Traceback (most recent call last):
  File "C:\Users\admin\AppData\Local\Programs\Python\Python311\Lib\site-packages\requests\models.py", line 971, in json
    return complexjson.loads(self.text, **kwargs)
           ^^^^^^^^^^^^^^^^^^^^^^^^^^^^^^^^^^^^^^
  File "C:\Users\admin\AppData\Local\Programs\Python\Python311\Lib\site-packages\simplejson\__init__.py", line 525, in loads
    return _default_decoder.decode(s)
           ^^^^^^^^^^^^^^^^^^^^^^^^^^
  File "C:\Users\admin\AppData\Local\Programs\Python\Python311\Lib\site-packages\simplejson\decoder.py", line 372, in decode
    obj, end = self.raw_decode(s)
               ^^^^^^^^^^^^^^^^^^
  File "C:\Users\admin\AppData\Local\Programs\Python\Python311\Lib\site-packages\simplejson\decoder.py", line 402, in raw_decode
    return self.scan_once(s, idx=_w(s, idx).end())
           ^^^^^^^^^^^^^^^^^^^^^^^^^^^^^^^^^^^^^^^
simplejson.errors.JSONDecodeError: Expecting value: line 1 column 1 (char 0)

During handling of the above exception, another exception occurred:

Traceback (most recent call last):
  File "C:\Users\admin\AppData\Local\Programs\Python\Python311\Lib\site-packages\django\core\handlers\exception.py", line 55, in inner
    response = get_response(request)
               ^^^^^^^^^^^^^^^^^^^^^
  File "C:\Users\admin\AppData\Local\Programs\Python\Python311\Lib\site-packages\django\core\handlers\base.py", line 197, in _get_response
    response = wrapped_callback(request, *callback_args, **callback_kwargs)
               ^^^^^^^^^^^^^^^^^^^^^^^^^^^^^^^^^^^^^^^^^^^^^^^^^^^^^^^^^^^^
  File "D:\项目\data_factory_platform\data_sync\views.py", line 48, in get_instance
    data_ = online.query_instance()
            ^^^^^^^^^^^^^^^^^^^^^^^
  File "D:\项目\data_factory_platform\data_sync\business\online_data_sync.py", line 20, in query_instance
    mysql_l = jsonpath(res.json(), '$..data[?(@.db_type=="mysql")].instance_name')
                       ^^^^^^^^^^
  File "C:\Users\admin\AppData\Local\Programs\Python\Python311\Lib\site-packages\requests\models.py", line 975, in json
    raise RequestsJSONDecodeError(e.msg, e.doc, e.pos)
requests.exceptions.JSONDecodeError: Expecting value: line 1 column 1 (char 0)
2023-04-29 18:36:16,005 [django.request:241] [log:log_response] [WARNING] Not Found: /factory/static/images/logo-sm.png
2023-04-29 18:36:16,006 [django.request:241] [log:log_response] [WARNING] Not Found: /factory/static/images/users/avatar-1.jpg
2023-04-29 18:36:16,367 [django.request:241] [log:log_response] [ERROR] Internal Server Error: /factory/sync/query_instance/
Traceback (most recent call last):
  File "C:\Users\admin\AppData\Local\Programs\Python\Python311\Lib\site-packages\requests\models.py", line 971, in json
    return complexjson.loads(self.text, **kwargs)
           ^^^^^^^^^^^^^^^^^^^^^^^^^^^^^^^^^^^^^^
  File "C:\Users\admin\AppData\Local\Programs\Python\Python311\Lib\site-packages\simplejson\__init__.py", line 525, in loads
    return _default_decoder.decode(s)
           ^^^^^^^^^^^^^^^^^^^^^^^^^^
  File "C:\Users\admin\AppData\Local\Programs\Python\Python311\Lib\site-packages\simplejson\decoder.py", line 372, in decode
    obj, end = self.raw_decode(s)
               ^^^^^^^^^^^^^^^^^^
  File "C:\Users\admin\AppData\Local\Programs\Python\Python311\Lib\site-packages\simplejson\decoder.py", line 402, in raw_decode
    return self.scan_once(s, idx=_w(s, idx).end())
           ^^^^^^^^^^^^^^^^^^^^^^^^^^^^^^^^^^^^^^^
simplejson.errors.JSONDecodeError: Expecting value: line 1 column 1 (char 0)

During handling of the above exception, another exception occurred:

Traceback (most recent call last):
  File "C:\Users\admin\AppData\Local\Programs\Python\Python311\Lib\site-packages\django\core\handlers\exception.py", line 55, in inner
    response = get_response(request)
               ^^^^^^^^^^^^^^^^^^^^^
  File "C:\Users\admin\AppData\Local\Programs\Python\Python311\Lib\site-packages\django\core\handlers\base.py", line 197, in _get_response
    response = wrapped_callback(request, *callback_args, **callback_kwargs)
               ^^^^^^^^^^^^^^^^^^^^^^^^^^^^^^^^^^^^^^^^^^^^^^^^^^^^^^^^^^^^
  File "D:\项目\data_factory_platform\data_sync\views.py", line 48, in get_instance
    data_ = online.query_instance()
            ^^^^^^^^^^^^^^^^^^^^^^^
  File "D:\项目\data_factory_platform\data_sync\business\online_data_sync.py", line 20, in query_instance
    mysql_l = jsonpath(res.json(), '$..data[?(@.db_type=="mysql")].instance_name')
                       ^^^^^^^^^^
  File "C:\Users\admin\AppData\Local\Programs\Python\Python311\Lib\site-packages\requests\models.py", line 975, in json
    raise RequestsJSONDecodeError(e.msg, e.doc, e.pos)
requests.exceptions.JSONDecodeError: Expecting value: line 1 column 1 (char 0)
2023-04-29 18:38:47,077 [django.request:241] [log:log_response] [WARNING] Not Found: /factory/static/images/logo-sm.png
2023-04-29 18:38:47,078 [django.request:241] [log:log_response] [WARNING] Not Found: /factory/static/images/users/avatar-1.jpg
2023-04-29 18:38:47,807 [django.request:241] [log:log_response] [ERROR] Internal Server Error: /factory/sync/query_instance/
Traceback (most recent call last):
  File "C:\Users\admin\AppData\Local\Programs\Python\Python311\Lib\site-packages\requests\models.py", line 971, in json
    return complexjson.loads(self.text, **kwargs)
           ^^^^^^^^^^^^^^^^^^^^^^^^^^^^^^^^^^^^^^
  File "C:\Users\admin\AppData\Local\Programs\Python\Python311\Lib\site-packages\simplejson\__init__.py", line 525, in loads
    return _default_decoder.decode(s)
           ^^^^^^^^^^^^^^^^^^^^^^^^^^
  File "C:\Users\admin\AppData\Local\Programs\Python\Python311\Lib\site-packages\simplejson\decoder.py", line 372, in decode
    obj, end = self.raw_decode(s)
               ^^^^^^^^^^^^^^^^^^
  File "C:\Users\admin\AppData\Local\Programs\Python\Python311\Lib\site-packages\simplejson\decoder.py", line 402, in raw_decode
    return self.scan_once(s, idx=_w(s, idx).end())
           ^^^^^^^^^^^^^^^^^^^^^^^^^^^^^^^^^^^^^^^
simplejson.errors.JSONDecodeError: Expecting value: line 1 column 1 (char 0)

During handling of the above exception, another exception occurred:

Traceback (most recent call last):
  File "C:\Users\admin\AppData\Local\Programs\Python\Python311\Lib\site-packages\django\core\handlers\exception.py", line 55, in inner
    response = get_response(request)
               ^^^^^^^^^^^^^^^^^^^^^
  File "C:\Users\admin\AppData\Local\Programs\Python\Python311\Lib\site-packages\django\core\handlers\base.py", line 197, in _get_response
    response = wrapped_callback(request, *callback_args, **callback_kwargs)
               ^^^^^^^^^^^^^^^^^^^^^^^^^^^^^^^^^^^^^^^^^^^^^^^^^^^^^^^^^^^^
  File "D:\项目\data_factory_platform\data_sync\views.py", line 48, in get_instance
    data_ = online.query_instance()
            ^^^^^^^^^^^^^^^^^^^^^^^
  File "D:\项目\data_factory_platform\data_sync\business\online_data_sync.py", line 20, in query_instance
    mysql_l = jsonpath(res.json(), '$..data[?(@.db_type=="mysql")].instance_name')
                       ^^^^^^^^^^
  File "C:\Users\admin\AppData\Local\Programs\Python\Python311\Lib\site-packages\requests\models.py", line 975, in json
    raise RequestsJSONDecodeError(e.msg, e.doc, e.pos)
requests.exceptions.JSONDecodeError: Expecting value: line 1 column 1 (char 0)
2023-04-29 18:38:49,616 [django.request:241] [log:log_response] [ERROR] Internal Server Error: /factory/query/
Traceback (most recent call last):
  File "C:\Users\admin\AppData\Local\Programs\Python\Python311\Lib\site-packages\requests\models.py", line 971, in json
    return complexjson.loads(self.text, **kwargs)
           ^^^^^^^^^^^^^^^^^^^^^^^^^^^^^^^^^^^^^^
  File "C:\Users\admin\AppData\Local\Programs\Python\Python311\Lib\site-packages\simplejson\__init__.py", line 525, in loads
    return _default_decoder.decode(s)
           ^^^^^^^^^^^^^^^^^^^^^^^^^^
  File "C:\Users\admin\AppData\Local\Programs\Python\Python311\Lib\site-packages\simplejson\decoder.py", line 372, in decode
    obj, end = self.raw_decode(s)
               ^^^^^^^^^^^^^^^^^^
  File "C:\Users\admin\AppData\Local\Programs\Python\Python311\Lib\site-packages\simplejson\decoder.py", line 402, in raw_decode
    return self.scan_once(s, idx=_w(s, idx).end())
           ^^^^^^^^^^^^^^^^^^^^^^^^^^^^^^^^^^^^^^^
simplejson.errors.JSONDecodeError: Expecting value: line 1 column 1 (char 0)

During handling of the above exception, another exception occurred:

Traceback (most recent call last):
  File "C:\Users\admin\AppData\Local\Programs\Python\Python311\Lib\site-packages\django\core\handlers\exception.py", line 55, in inner
    response = get_response(request)
               ^^^^^^^^^^^^^^^^^^^^^
  File "C:\Users\admin\AppData\Local\Programs\Python\Python311\Lib\site-packages\django\core\handlers\base.py", line 197, in _get_response
    response = wrapped_callback(request, *callback_args, **callback_kwargs)
               ^^^^^^^^^^^^^^^^^^^^^^^^^^^^^^^^^^^^^^^^^^^^^^^^^^^^^^^^^^^^
  File "C:\Users\admin\AppData\Local\Programs\Python\Python311\Lib\site-packages\django\views\decorators\csrf.py", line 54, in wrapped_view
    return view_func(*args, **kwargs)
           ^^^^^^^^^^^^^^^^^^^^^^^^^^
  File "D:\项目\data_factory_platform\data_sync\views.py", line 89, in query
    data = on.query({
           ^^^^^^^^^^
  File "D:\项目\data_factory_platform\data_sync\business\online_data_sync.py", line 55, in query
    return res.json()
           ^^^^^^^^^^
  File "C:\Users\admin\AppData\Local\Programs\Python\Python311\Lib\site-packages\requests\models.py", line 975, in json
    raise RequestsJSONDecodeError(e.msg, e.doc, e.pos)
requests.exceptions.JSONDecodeError: Expecting value: line 1 column 1 (char 0)
2023-04-29 18:39:59,108 [django.request:241] [log:log_response] [WARNING] Not Found: /factory/static/images/users/avatar-1.jpg
2023-04-29 18:39:59,109 [django.request:241] [log:log_response] [WARNING] Not Found: /factory/static/images/logo-sm.png
2023-04-29 18:39:59,608 [django.request:241] [log:log_response] [ERROR] Internal Server Error: /factory/sync/query_instance/
Traceback (most recent call last):
  File "C:\Users\admin\AppData\Local\Programs\Python\Python311\Lib\site-packages\requests\models.py", line 971, in json
    return complexjson.loads(self.text, **kwargs)
           ^^^^^^^^^^^^^^^^^^^^^^^^^^^^^^^^^^^^^^
  File "C:\Users\admin\AppData\Local\Programs\Python\Python311\Lib\site-packages\simplejson\__init__.py", line 525, in loads
    return _default_decoder.decode(s)
           ^^^^^^^^^^^^^^^^^^^^^^^^^^
  File "C:\Users\admin\AppData\Local\Programs\Python\Python311\Lib\site-packages\simplejson\decoder.py", line 372, in decode
    obj, end = self.raw_decode(s)
               ^^^^^^^^^^^^^^^^^^
  File "C:\Users\admin\AppData\Local\Programs\Python\Python311\Lib\site-packages\simplejson\decoder.py", line 402, in raw_decode
    return self.scan_once(s, idx=_w(s, idx).end())
           ^^^^^^^^^^^^^^^^^^^^^^^^^^^^^^^^^^^^^^^
simplejson.errors.JSONDecodeError: Expecting value: line 1 column 1 (char 0)

During handling of the above exception, another exception occurred:

Traceback (most recent call last):
  File "C:\Users\admin\AppData\Local\Programs\Python\Python311\Lib\site-packages\django\core\handlers\exception.py", line 55, in inner
    response = get_response(request)
               ^^^^^^^^^^^^^^^^^^^^^
  File "C:\Users\admin\AppData\Local\Programs\Python\Python311\Lib\site-packages\django\core\handlers\base.py", line 197, in _get_response
    response = wrapped_callback(request, *callback_args, **callback_kwargs)
               ^^^^^^^^^^^^^^^^^^^^^^^^^^^^^^^^^^^^^^^^^^^^^^^^^^^^^^^^^^^^
  File "D:\项目\data_factory_platform\data_sync\views.py", line 48, in get_instance
    data_ = online.query_instance()
            ^^^^^^^^^^^^^^^^^^^^^^^
  File "D:\项目\data_factory_platform\data_sync\business\online_data_sync.py", line 20, in query_instance
    mysql_l = jsonpath(res.json(), '$..data[?(@.db_type=="mysql")].instance_name')
                       ^^^^^^^^^^
  File "C:\Users\admin\AppData\Local\Programs\Python\Python311\Lib\site-packages\requests\models.py", line 975, in json
    raise RequestsJSONDecodeError(e.msg, e.doc, e.pos)
requests.exceptions.JSONDecodeError: Expecting value: line 1 column 1 (char 0)
2023-04-29 18:40:01,674 [django.request:241] [log:log_response] [ERROR] Internal Server Error: /factory/query/
Traceback (most recent call last):
  File "C:\Users\admin\AppData\Local\Programs\Python\Python311\Lib\site-packages\requests\models.py", line 971, in json
    return complexjson.loads(self.text, **kwargs)
           ^^^^^^^^^^^^^^^^^^^^^^^^^^^^^^^^^^^^^^
  File "C:\Users\admin\AppData\Local\Programs\Python\Python311\Lib\site-packages\simplejson\__init__.py", line 525, in loads
    return _default_decoder.decode(s)
           ^^^^^^^^^^^^^^^^^^^^^^^^^^
  File "C:\Users\admin\AppData\Local\Programs\Python\Python311\Lib\site-packages\simplejson\decoder.py", line 372, in decode
    obj, end = self.raw_decode(s)
               ^^^^^^^^^^^^^^^^^^
  File "C:\Users\admin\AppData\Local\Programs\Python\Python311\Lib\site-packages\simplejson\decoder.py", line 402, in raw_decode
    return self.scan_once(s, idx=_w(s, idx).end())
           ^^^^^^^^^^^^^^^^^^^^^^^^^^^^^^^^^^^^^^^
simplejson.errors.JSONDecodeError: Expecting value: line 1 column 1 (char 0)

During handling of the above exception, another exception occurred:

Traceback (most recent call last):
  File "C:\Users\admin\AppData\Local\Programs\Python\Python311\Lib\site-packages\django\core\handlers\exception.py", line 55, in inner
    response = get_response(request)
               ^^^^^^^^^^^^^^^^^^^^^
  File "C:\Users\admin\AppData\Local\Programs\Python\Python311\Lib\site-packages\django\core\handlers\base.py", line 197, in _get_response
    response = wrapped_callback(request, *callback_args, **callback_kwargs)
               ^^^^^^^^^^^^^^^^^^^^^^^^^^^^^^^^^^^^^^^^^^^^^^^^^^^^^^^^^^^^
  File "C:\Users\admin\AppData\Local\Programs\Python\Python311\Lib\site-packages\django\views\decorators\csrf.py", line 54, in wrapped_view
    return view_func(*args, **kwargs)
           ^^^^^^^^^^^^^^^^^^^^^^^^^^
  File "D:\项目\data_factory_platform\data_sync\views.py", line 89, in query
    data = on.query({
           ^^^^^^^^^^
  File "D:\项目\data_factory_platform\data_sync\business\online_data_sync.py", line 55, in query
    return res.json()
           ^^^^^^^^^^
  File "C:\Users\admin\AppData\Local\Programs\Python\Python311\Lib\site-packages\requests\models.py", line 975, in json
    raise RequestsJSONDecodeError(e.msg, e.doc, e.pos)
requests.exceptions.JSONDecodeError: Expecting value: line 1 column 1 (char 0)
2023-04-29 18:40:14,701 [django.request:241] [log:log_response] [ERROR] Internal Server Error: /factory/sync/query_instance/
Traceback (most recent call last):
  File "C:\Users\admin\AppData\Local\Programs\Python\Python311\Lib\site-packages\requests\models.py", line 971, in json
    return complexjson.loads(self.text, **kwargs)
           ^^^^^^^^^^^^^^^^^^^^^^^^^^^^^^^^^^^^^^
  File "C:\Users\admin\AppData\Local\Programs\Python\Python311\Lib\site-packages\simplejson\__init__.py", line 525, in loads
    return _default_decoder.decode(s)
           ^^^^^^^^^^^^^^^^^^^^^^^^^^
  File "C:\Users\admin\AppData\Local\Programs\Python\Python311\Lib\site-packages\simplejson\decoder.py", line 372, in decode
    obj, end = self.raw_decode(s)
               ^^^^^^^^^^^^^^^^^^
  File "C:\Users\admin\AppData\Local\Programs\Python\Python311\Lib\site-packages\simplejson\decoder.py", line 402, in raw_decode
    return self.scan_once(s, idx=_w(s, idx).end())
           ^^^^^^^^^^^^^^^^^^^^^^^^^^^^^^^^^^^^^^^
simplejson.errors.JSONDecodeError: Expecting value: line 1 column 1 (char 0)

During handling of the above exception, another exception occurred:

Traceback (most recent call last):
  File "C:\Users\admin\AppData\Local\Programs\Python\Python311\Lib\site-packages\django\core\handlers\exception.py", line 55, in inner
    response = get_response(request)
               ^^^^^^^^^^^^^^^^^^^^^
  File "C:\Users\admin\AppData\Local\Programs\Python\Python311\Lib\site-packages\django\core\handlers\base.py", line 197, in _get_response
    response = wrapped_callback(request, *callback_args, **callback_kwargs)
               ^^^^^^^^^^^^^^^^^^^^^^^^^^^^^^^^^^^^^^^^^^^^^^^^^^^^^^^^^^^^
  File "D:\项目\data_factory_platform\data_sync\views.py", line 48, in get_instance
    data_ = online.query_instance()
            ^^^^^^^^^^^^^^^^^^^^^^^
  File "D:\项目\data_factory_platform\data_sync\business\online_data_sync.py", line 20, in query_instance
    mysql_l = jsonpath(res.json(), '$..data[?(@.db_type=="mysql")].instance_name')
                       ^^^^^^^^^^
  File "C:\Users\admin\AppData\Local\Programs\Python\Python311\Lib\site-packages\requests\models.py", line 975, in json
    raise RequestsJSONDecodeError(e.msg, e.doc, e.pos)
requests.exceptions.JSONDecodeError: Expecting value: line 1 column 1 (char 0)
2023-04-29 18:40:14,857 [django.request:241] [log:log_response] [WARNING] Not Found: /favicon.ico
2023-04-29 18:41:26,712 [django.request:241] [log:log_response] [WARNING] Not Found: /factory/static/images/users/avatar-1.jpg
2023-04-29 18:41:26,713 [django.request:241] [log:log_response] [WARNING] Not Found: /factory/static/images/logo-sm.png
2023-04-29 18:41:27,552 [django.request:241] [log:log_response] [ERROR] Internal Server Error: /factory/sync/query_instance/
Traceback (most recent call last):
  File "C:\Users\admin\AppData\Local\Programs\Python\Python311\Lib\site-packages\requests\models.py", line 971, in json
    return complexjson.loads(self.text, **kwargs)
           ^^^^^^^^^^^^^^^^^^^^^^^^^^^^^^^^^^^^^^
  File "C:\Users\admin\AppData\Local\Programs\Python\Python311\Lib\site-packages\simplejson\__init__.py", line 525, in loads
    return _default_decoder.decode(s)
           ^^^^^^^^^^^^^^^^^^^^^^^^^^
  File "C:\Users\admin\AppData\Local\Programs\Python\Python311\Lib\site-packages\simplejson\decoder.py", line 372, in decode
    obj, end = self.raw_decode(s)
               ^^^^^^^^^^^^^^^^^^
  File "C:\Users\admin\AppData\Local\Programs\Python\Python311\Lib\site-packages\simplejson\decoder.py", line 402, in raw_decode
    return self.scan_once(s, idx=_w(s, idx).end())
           ^^^^^^^^^^^^^^^^^^^^^^^^^^^^^^^^^^^^^^^
simplejson.errors.JSONDecodeError: Expecting value: line 1 column 1 (char 0)

During handling of the above exception, another exception occurred:

Traceback (most recent call last):
  File "C:\Users\admin\AppData\Local\Programs\Python\Python311\Lib\site-packages\django\core\handlers\exception.py", line 55, in inner
    response = get_response(request)
               ^^^^^^^^^^^^^^^^^^^^^
  File "C:\Users\admin\AppData\Local\Programs\Python\Python311\Lib\site-packages\django\core\handlers\base.py", line 197, in _get_response
    response = wrapped_callback(request, *callback_args, **callback_kwargs)
               ^^^^^^^^^^^^^^^^^^^^^^^^^^^^^^^^^^^^^^^^^^^^^^^^^^^^^^^^^^^^
  File "D:\项目\data_factory_platform\data_sync\views.py", line 48, in get_instance
    data_ = online.query_instance()
            ^^^^^^^^^^^^^^^^^^^^^^^
  File "D:\项目\data_factory_platform\data_sync\business\online_data_sync.py", line 20, in query_instance
    mysql_l = jsonpath(res.json(), '$..data[?(@.db_type=="mysql")].instance_name')
                       ^^^^^^^^^^
  File "C:\Users\admin\AppData\Local\Programs\Python\Python311\Lib\site-packages\requests\models.py", line 975, in json
    raise RequestsJSONDecodeError(e.msg, e.doc, e.pos)
requests.exceptions.JSONDecodeError: Expecting value: line 1 column 1 (char 0)
2023-04-29 18:41:27,609 [django.request:241] [log:log_response] [WARNING] Not Found: /factory/static/images/favicon.ico
2023-04-29 18:41:34,768 [django.request:241] [log:log_response] [ERROR] Internal Server Error: /factory/query/
Traceback (most recent call last):
  File "C:\Users\admin\AppData\Local\Programs\Python\Python311\Lib\site-packages\requests\models.py", line 971, in json
    return complexjson.loads(self.text, **kwargs)
           ^^^^^^^^^^^^^^^^^^^^^^^^^^^^^^^^^^^^^^
  File "C:\Users\admin\AppData\Local\Programs\Python\Python311\Lib\site-packages\simplejson\__init__.py", line 525, in loads
    return _default_decoder.decode(s)
           ^^^^^^^^^^^^^^^^^^^^^^^^^^
  File "C:\Users\admin\AppData\Local\Programs\Python\Python311\Lib\site-packages\simplejson\decoder.py", line 372, in decode
    obj, end = self.raw_decode(s)
               ^^^^^^^^^^^^^^^^^^
  File "C:\Users\admin\AppData\Local\Programs\Python\Python311\Lib\site-packages\simplejson\decoder.py", line 402, in raw_decode
    return self.scan_once(s, idx=_w(s, idx).end())
           ^^^^^^^^^^^^^^^^^^^^^^^^^^^^^^^^^^^^^^^
simplejson.errors.JSONDecodeError: Expecting value: line 1 column 1 (char 0)

During handling of the above exception, another exception occurred:

Traceback (most recent call last):
  File "C:\Users\admin\AppData\Local\Programs\Python\Python311\Lib\site-packages\django\core\handlers\exception.py", line 55, in inner
    response = get_response(request)
               ^^^^^^^^^^^^^^^^^^^^^
  File "C:\Users\admin\AppData\Local\Programs\Python\Python311\Lib\site-packages\django\core\handlers\base.py", line 197, in _get_response
    response = wrapped_callback(request, *callback_args, **callback_kwargs)
               ^^^^^^^^^^^^^^^^^^^^^^^^^^^^^^^^^^^^^^^^^^^^^^^^^^^^^^^^^^^^
  File "C:\Users\admin\AppData\Local\Programs\Python\Python311\Lib\site-packages\django\views\decorators\csrf.py", line 54, in wrapped_view
    return view_func(*args, **kwargs)
           ^^^^^^^^^^^^^^^^^^^^^^^^^^
  File "D:\项目\data_factory_platform\data_sync\views.py", line 89, in query
    data = on.query({
           ^^^^^^^^^^
  File "D:\项目\data_factory_platform\data_sync\business\online_data_sync.py", line 55, in query
    return res.json()
           ^^^^^^^^^^
  File "C:\Users\admin\AppData\Local\Programs\Python\Python311\Lib\site-packages\requests\models.py", line 975, in json
    raise RequestsJSONDecodeError(e.msg, e.doc, e.pos)
requests.exceptions.JSONDecodeError: Expecting value: line 1 column 1 (char 0)
2023-04-29 18:47:21,908 [django.request:241] [log:log_response] [ERROR] Internal Server Error: /factory/query/
Traceback (most recent call last):
  File "C:\Users\admin\AppData\Local\Programs\Python\Python311\Lib\site-packages\requests\models.py", line 971, in json
    return complexjson.loads(self.text, **kwargs)
           ^^^^^^^^^^^^^^^^^^^^^^^^^^^^^^^^^^^^^^
  File "C:\Users\admin\AppData\Local\Programs\Python\Python311\Lib\site-packages\simplejson\__init__.py", line 525, in loads
    return _default_decoder.decode(s)
           ^^^^^^^^^^^^^^^^^^^^^^^^^^
  File "C:\Users\admin\AppData\Local\Programs\Python\Python311\Lib\site-packages\simplejson\decoder.py", line 372, in decode
    obj, end = self.raw_decode(s)
               ^^^^^^^^^^^^^^^^^^
  File "C:\Users\admin\AppData\Local\Programs\Python\Python311\Lib\site-packages\simplejson\decoder.py", line 402, in raw_decode
    return self.scan_once(s, idx=_w(s, idx).end())
           ^^^^^^^^^^^^^^^^^^^^^^^^^^^^^^^^^^^^^^^
simplejson.errors.JSONDecodeError: Expecting value: line 1 column 1 (char 0)

During handling of the above exception, another exception occurred:

Traceback (most recent call last):
  File "C:\Users\admin\AppData\Local\Programs\Python\Python311\Lib\site-packages\django\core\handlers\exception.py", line 55, in inner
    response = get_response(request)
               ^^^^^^^^^^^^^^^^^^^^^
  File "C:\Users\admin\AppData\Local\Programs\Python\Python311\Lib\site-packages\django\core\handlers\base.py", line 197, in _get_response
    response = wrapped_callback(request, *callback_args, **callback_kwargs)
               ^^^^^^^^^^^^^^^^^^^^^^^^^^^^^^^^^^^^^^^^^^^^^^^^^^^^^^^^^^^^
  File "C:\Users\admin\AppData\Local\Programs\Python\Python311\Lib\site-packages\django\views\decorators\csrf.py", line 54, in wrapped_view
    return view_func(*args, **kwargs)
           ^^^^^^^^^^^^^^^^^^^^^^^^^^
  File "D:\项目\data_factory_platform\data_sync\views.py", line 89, in query
    data = on.query({
           ^^^^^^^^^^
  File "D:\项目\data_factory_platform\data_sync\business\online_data_sync.py", line 55, in query
    return res.json()
           ^^^^^^^^^^
  File "C:\Users\admin\AppData\Local\Programs\Python\Python311\Lib\site-packages\requests\models.py", line 975, in json
    raise RequestsJSONDecodeError(e.msg, e.doc, e.pos)
requests.exceptions.JSONDecodeError: Expecting value: line 1 column 1 (char 0)
