2023-05-19 09:38:09,790 [django.request:241] [log:log_response] [WARNING] Not Found: /favicon.ico
2023-05-19 09:38:19,277 [django.request:241] [log:log_response] [WARNING] Not Found: /register/127.0.0.1:8001/register/
2023-05-19 09:38:50,879 [django.request:241] [log:log_response] [WARNING] Not Found: /register/127.0.0.1:8001/register/
2023-05-19 09:40:05,819 [django.request:241] [log:log_response] [WARNING] Not Found: /favicon.ico
2023-05-19 09:40:10,213 [django.request:241] [log:log_response] [WARNING] Not Found: /register/127.0.0.1:8001/register/
2023-05-19 09:40:18,209 [django.request:241] [log:log_response] [WARNING] Not Found: /register/127.0.0.1:8001/register/
2023-05-19 09:41:51,767 [django.request:241] [log:log_response] [WARNING] Not Found: /favicon.ico
2023-05-19 09:41:54,868 [django.request:241] [log:log_response] [WARNING] Not Found: /register/127.0.0.1:8001/register/
2023-05-19 09:42:09,865 [django.request:241] [log:log_response] [WARNING] Not Found: /register/127.0.0.1:8001/register/
2023-05-19 09:43:00,850 [django.request:241] [log:log_response] [WARNING] Not Found: /favicon.ico
2023-05-19 09:45:11,142 [django.request:241] [log:log_response] [WARNING] Not Found: /register/127.0.0.1:8001/register/
2023-05-19 11:38:20,036 [django.request:241] [log:log_response] [WARNING] Not Found: /register/127.0.0.1:8001/register/
2023-05-22 13:52:26,297 [django.request:241] [log:log_response] [WARNING] Not Found: /factory/index/
2023-05-22 13:52:26,363 [django.request:241] [log:log_response] [WARNING] Not Found: /favicon.ico
2023-05-22 13:53:00,162 [django.request:241] [log:log_response] [WARNING] Not Found: /factory/data_sync/form-elements.html
2023-05-22 13:53:14,039 [django.request:241] [log:log_response] [ERROR] Internal Server Error: /factory/intranet/add/
Traceback (most recent call last):
  File "C:\Users\admin\AppData\Local\Programs\Python\Python311\Lib\site-packages\django\db\backends\mysql\base.py", line 75, in execute
    return self.cursor.execute(query, args)
           ^^^^^^^^^^^^^^^^^^^^^^^^^^^^^^^^
  File "C:\Users\admin\AppData\Local\Programs\Python\Python311\Lib\site-packages\MySQLdb\cursors.py", line 206, in execute
    res = self._query(query)
          ^^^^^^^^^^^^^^^^^^
  File "C:\Users\admin\AppData\Local\Programs\Python\Python311\Lib\site-packages\MySQLdb\cursors.py", line 319, in _query
    db.query(q)
  File "C:\Users\admin\AppData\Local\Programs\Python\Python311\Lib\site-packages\MySQLdb\connections.py", line 254, in query
    _mysql.connection.query(self, query)
MySQLdb.OperationalError: (1048, "Column 'name' cannot be null")

During handling of the above exception, another exception occurred:

Traceback (most recent call last):
  File "C:\Users\admin\AppData\Local\Programs\Python\Python311\Lib\site-packages\django\core\handlers\exception.py", line 55, in inner
    response = get_response(request)
               ^^^^^^^^^^^^^^^^^^^^^
  File "C:\Users\admin\AppData\Local\Programs\Python\Python311\Lib\site-packages\django\core\handlers\base.py", line 197, in _get_response
    response = wrapped_callback(request, *callback_args, **callback_kwargs)
               ^^^^^^^^^^^^^^^^^^^^^^^^^^^^^^^^^^^^^^^^^^^^^^^^^^^^^^^^^^^^
  File "C:\Users\admin\AppData\Local\Programs\Python\Python311\Lib\site-packages\django\views\decorators\csrf.py", line 54, in wrapped_view
    return view_func(*args, **kwargs)
           ^^^^^^^^^^^^^^^^^^^^^^^^^^
  File "D:\ÏîÄ¿\data_factory_platform\data_sync\views.py", line 160, in add_intranet_config
    obj = DataFactoryIntranetConfig.objects.create(name=name, host=host, user=user, password=password, port=port,
          ^^^^^^^^^^^^^^^^^^^^^^^^^^^^^^^^^^^^^^^^^^^^^^^^^^^^^^^^^^^^^^^^^^^^^^^^^^^^^^^^^^^^^^^^^^^^^^^^^^^^^^^
  File "C:\Users\admin\AppData\Local\Programs\Python\Python311\Lib\site-packages\django\db\models\manager.py", line 85, in manager_method
    return getattr(self.get_queryset(), name)(*args, **kwargs)
           ^^^^^^^^^^^^^^^^^^^^^^^^^^^^^^^^^^^^^^^^^^^^^^^^^^^
  File "C:\Users\admin\AppData\Local\Programs\Python\Python311\Lib\site-packages\django\db\models\query.py", line 671, in create
    obj.save(force_insert=True, using=self.db)
  File "C:\Users\admin\AppData\Local\Programs\Python\Python311\Lib\site-packages\django\db\models\base.py", line 812, in save
    self.save_base(
  File "C:\Users\admin\AppData\Local\Programs\Python\Python311\Lib\site-packages\django\db\models\base.py", line 863, in save_base
    updated = self._save_table(
              ^^^^^^^^^^^^^^^^^
  File "C:\Users\admin\AppData\Local\Programs\Python\Python311\Lib\site-packages\django\db\models\base.py", line 1006, in _save_table
    results = self._do_insert(
              ^^^^^^^^^^^^^^^^
  File "C:\Users\admin\AppData\Local\Programs\Python\Python311\Lib\site-packages\django\db\models\base.py", line 1047, in _do_insert
    return manager._insert(
           ^^^^^^^^^^^^^^^^
  File "C:\Users\admin\AppData\Local\Programs\Python\Python311\Lib\site-packages\django\db\models\manager.py", line 85, in manager_method
    return getattr(self.get_queryset(), name)(*args, **kwargs)
           ^^^^^^^^^^^^^^^^^^^^^^^^^^^^^^^^^^^^^^^^^^^^^^^^^^^
  File "C:\Users\admin\AppData\Local\Programs\Python\Python311\Lib\site-packages\django\db\models\query.py", line 1790, in _insert
    return query.get_compiler(using=using).execute_sql(returning_fields)
           ^^^^^^^^^^^^^^^^^^^^^^^^^^^^^^^^^^^^^^^^^^^^^^^^^^^^^^^^^^^^^
  File "C:\Users\admin\AppData\Local\Programs\Python\Python311\Lib\site-packages\django\db\models\sql\compiler.py", line 1660, in execute_sql
    cursor.execute(sql, params)
  File "C:\Users\admin\AppData\Local\Programs\Python\Python311\Lib\site-packages\django\db\backends\utils.py", line 103, in execute
    return super().execute(sql, params)
           ^^^^^^^^^^^^^^^^^^^^^^^^^^^^
  File "C:\Users\admin\AppData\Local\Programs\Python\Python311\Lib\site-packages\django\db\backends\utils.py", line 67, in execute
    return self._execute_with_wrappers(
           ^^^^^^^^^^^^^^^^^^^^^^^^^^^^
  File "C:\Users\admin\AppData\Local\Programs\Python\Python311\Lib\site-packages\django\db\backends\utils.py", line 80, in _execute_with_wrappers
    return executor(sql, params, many, context)
           ^^^^^^^^^^^^^^^^^^^^^^^^^^^^^^^^^^^^
  File "C:\Users\admin\AppData\Local\Programs\Python\Python311\Lib\site-packages\django\db\backends\utils.py", line 89, in _execute
    return self.cursor.execute(sql, params)
           ^^^^^^^^^^^^^^^^^^^^^^^^^^^^^^^^
  File "C:\Users\admin\AppData\Local\Programs\Python\Python311\Lib\site-packages\django\db\backends\mysql\base.py", line 80, in execute
    raise IntegrityError(*tuple(e.args))
django.db.utils.IntegrityError: (1048, "Column 'name' cannot be null")
